2022-05-23 02:28:28,127 [DEBUG] py4...: Calling cytoscape_ping()
2022-05-23 02:28:28,127 [DEBUG] py4...: ǀCalling cytoscape_version_info(base_url='http://127.0.0.1:1234/v1')
2022-05-23 02:28:28,127 [DEBUG] py4...: ǀǀCalling cyrest_get('version', base_url='http://127.0.0.1:1234/v1')
2022-05-23 02:28:28,127 [DEBUG] py4...: ǀǀHTTP GET(http://127.0.0.1:1234/v1/version)
2022-05-23 02:28:28,133 [DEBUG] py4...: ǀǀ'cyrest_get' exception ConnectionError(MaxRetryError("HTTPConnectionPool(host='127.0.0.1', port=1234): Max retries exceeded with url: /v1/version (Caused by NewConnectionError('<urllib3.connection.HTTPConnection object at 0x125582b80>: Failed to establish a new connection: [Errno 61] Connection refused'))"))
2022-05-23 02:28:28,133 [DEBUG] py4...: ǀ'cytoscape_version_info' exception ConnectionError(MaxRetryError("HTTPConnectionPool(host='127.0.0.1', port=1234): Max retries exceeded with url: /v1/version (Caused by NewConnectionError('<urllib3.connection.HTTPConnection object at 0x125582b80>: Failed to establish a new connection: [Errno 61] Connection refused'))"))
2022-05-23 02:28:28,133 [DEBUG] py4...: 'cytoscape_ping' exception ConnectionError(MaxRetryError("HTTPConnectionPool(host='127.0.0.1', port=1234): Max retries exceeded with url: /v1/version (Caused by NewConnectionError('<urllib3.connection.HTTPConnection object at 0x125582b80>: Failed to establish a new connection: [Errno 61] Connection refused'))"))
2022-05-23 02:28:28,133 [DEBUG] py4...: --------------------
